Workbook
Name HigherCutOff: 'Staging Data'!$AH$3
Name LowerCutOff: 'Staging Data'!$AH$2
Name Slicer_Channel: #N/A
Name Slicer_Country: #N/A
Name Slicer_Country1: #N/A
Name Slicer_Month: #N/A
Name Slicer_ProductCategory: #N/A
Name Slicer_Region1: #N/A
Name Slicer_Salesperson: #N/A
Name Slicer_Year: #N/A

Sheet Country Vs Monthly Revenue
A3: Row Labels | B3: Sum of GrossRevenue
A4: Kenya | B4: 936159.62
A5: Q1-2023 | B5: 121681.01
A6: 1-2023 | B6: 47962.718
A7: 2-2023 | B7: 3115.3609
A8: 3-2023 | B8: 70602.928
A9: Q1-2024 | B9: 71718.458
A10: 2-2024 | B10: 66852.129
A11: 3-2024 | B11: 4866.3288
A12: Q1-2025 | B12: 82139.658
A13: Q2-2023 | B13: 25750.282
A14: 4-2023 | B14: 11003.767
A15: 5-2023 | B15: 10946.712
... A42: Grand Total | B42: 936159.62

Sheet SKU and ProductCategory vs Reve
A3: Row Labels | B3: Sum of GrossRevenue
A4: Accessories | B4: 155317.69
A5: ACC-2988 | B5: 53034.364
A6: ACC-1659 | B6: 28386.016
A7: ACC-1238 | B7: 17067.938
A8: ACC-5144 | B8: 15860.782
A9: ACC-7354 | B9: 13108.786
A10: ACC-4124 | B10: 11015.51
A11: ACC-1028 | B11: 10693.885
A12: ACC-2252 | B12: 4569.8508
A13: ACC-4766 | B13: 1030.7574
A14: ACC-9820 | B14: 549.8001
A15: Components | B15: 121717.08
... A62: Grand Total | B62: 923279.52

Sheet Salesperson Productivity
A3: Row Labels | B3: Count of OrderID | C3: Sum of GrossProfit
A4: F. Müller | B4: 1 | C4: 5243.9374
A5: J. Njeri | B5: 1 | C5: 17.50437
A6: Grand Total | B6: 2 | C6: 5261.4417

Sheet Online Cannibalizing Retail
A3: Sum of GrossRevenue | B3: Column Labels
A4: Row Labels | B4: Online | C4: Retail | D4: Grand Total
A5: Africa | B5: 128525.96 | C5: 276653.08 | D5: 405179.04
A6: Grand Total | B6: 128525.96 | C6: 276653.08 | D6: 405179.04

Sheet LeadTimeDays vs OrderID
A3: Row Labels | B3: Count of OrderID
A4: No | B4: 0.6
A5: Yes | B5: 0.4
A6: Grand Total | B6: 1

Sheet DiscountPct > 20% by Region and
A3: Row Labels | B3: Count of OrderID
A4: No | B4: 3
A5: Yes | B5: 2
A6: Grand Total | B6: 5

Sheet RevenueByMonth
A3: Sum of GrossRevenue | B3: Column Labels
A4: Row Labels | B4: 2023 | C4: 2024 | D4: 2025 | E4: Grand Total
A5: Jan | B5: 47962.718 | D5: 52609.066 | E5: 100571.78
A6: Feb | B6: 3115.3609 | C6: 66852.129 | D6: 15860.782 | E6: 85828.272
A7: Mar | B7: 70602.928 | C7: 4866.3288 | D7: 13669.81 | E7: 89139.067
A8: Apr | B8: 11003.767 | C8: 24447.959 | D8: 17731.623 | E8: 53183.349
A9: May | B9: 10946.712 | C9: 13108.786 | D9: 4569.8508 | E9: 28625.348
A10: Jun | B10: 3799.8031 | C10: 181608.7 | E10: 185408.5
A11: Jul | B11: 36649.808 | C11: 27763.018 | D11: 17867.219 | E11: 82280.046
A12: Aug | B12: 667.74 | C12: 3823.6152 | D12: 15174.426 | E12: 19665.781
A13: Sep | B13: 1030.7574 | C13: 52863.981 | D13: 9050.5053 | E13: 62945.244
A14: Oct | B14: 38264.51 | C14: 50650.006 | E14: 88914.516
A15: Nov | C15: 123535.74 | E15: 123535.74
A16: Dec | B16: 16061.973 | E16: 16061.973
A17: Grand Total | B17: 240106.08 | C17: 549520.26 | D17: 146533.28 | E17: 936159.62

Sheet DiscountOutliers
B1: DiscountPct
B2: 0
B3: 0.14
B4: 0.089
B5: 0
B6: 0.057
B7: 0.194
B8: 0.066
B9: 0.243
B10: 0.111
B11: 0.196
B12: 0.089
B13: 0.22
... B633: 0.168

Sheet ProfitbyRegionandChannel
A3: Sum of GrossProfit | B3: Column Labels
A4: Row Labels | B4: Africa | C4: Grand Total
A5: Direct | B5: 113946.29 | C5: 113946.29
A6: Distributor | B6: 58662.09 | C6: 58662.09
A7: Marketplace | B7: 2699.974 | C7: 2699.974
A8: N/A | B8: -149.6334 | C8: -149.6334
A9: Online | B9: 50056.937 | C9: 50056.937
A10: Retail | B10: 50680.042 | C10: 50680.042
A11: Grand Total | B11: 275895.7 | C11: 275895.7

Sheet Dashboard
C3: • Global Discount Cap (e.g., 0%–25%). | D3: 0.2
C4: • UnitCost inflation factor (e.g., 0%–15%). | D4: 0.05
C5: • Quantity uplift (e.g., 0%–20%). | D5: 0.15
F12: ='Staging Data'!X634 -> 10928846 | I12: ='Staging Data'!Z634 -> 3401098 | M12: ='Staging Data'!AM2 -> 0.31120377 | Q12: ='Staging Data'!AO2 -> 17292.477 | U12: ='Staging Data'!AP2 -> 0.74683544

Sheet ReadMe
A1: To clear the duplicates, Select the whole data the got to Data and Press Remove Duplicates
A2: To fix the data types to numeric figures, Change the Entries to either Short dates or numbers at the Number section
A3: To handle missing City, Salesperson and Channel, press Ctrl H, Find the Blanks then replace with N/A
A4: After flagging the negative prices and discount>30% use the following. For negative prices, Use ABS function. Highlight the discountpct colum and using Conditional formatting highligh values >30%.
A5: To ensure RequiredDate is not earlier than OrderDate, I used the formula =IF([@RequiredDate]>[@OrderDate],[@RequiredDate],[@OrderDate])
A6: After creating new RequiredDate and OrderDate I used it to create NLTD which is a column standing for NewLeadTimeDays
A7: To derive MMM-YYYY from OrderDate I used the formula: =CONCAT(MONTH(OrderDate),"-",YEAR(OrderDate)) where "CONCAT" is short for "CONCATNET" which means joining the month and the year. Another formula you can use is: =TEXT(OrderDate, "MMM-YYYY")
A8: To get the different quarters, Use the formula: =Q"&ROUNDUP(MONTH(OrderDate)/3,0)&"-"&YEAR(OrderDate) where "ROUNDUP" stand for putting the months together and categorizing them into quarters.
A9: To get the Region Hierarchy Use the formula: =CONCAT(Region," →",Country," →",City)
A10: To create the PriceBand column, Use the formula: =IF(UnitPrice<=LowerCutOff,"Low", IF(UnitPrice<=HigherCutOff,"Medium","High"))
A11: To identify the first month each Country appears and calculate monthly revenue tracked from that start, Insert a Pivot Table and put Country, Quarter and Month in the Rows and Sum Of GrossRevenue in the values section. Then create a Slicer for the country
A12: To classify SKUs into A (top 80%), B (next 15%), C (last 5%) of revenue per category, Create a Pivot Table and Put SKU and ProductCategory in the Rows and SumofGrossRevenue in Values. Then per every SKU, Calculate 80%, 15% and 5% percentiles highlighting each with a different color.
... A19: To get Quantity Uplift, I assumed that my Quantity Uplift is 15% then created a new folder called Quantity Uplift. I then used the following formula: =(100%+Dashboard!$D$5)*'Staging Data'!W3. Where W3 is the Quantity and D4 is the assumed Quantity Uplift

Sheet Staging Data
A1: OrderID | B1: OrderDate | C1: RequiredDate | D1: new od | E1: New RD | F1: New LTD | G1: New RequiredDate | H1: LeadTimeDays | I1: 7 LeadTimeDays | J1: Greater than 20% Discount | K1: Region | L1: Country | M1: City | N1: CustomerSegment | O1: Channel | P1: Salesperson | Q1: ProductCategory | R1: SKU | S1: UnitCost | T1: UnitPrice | U1: Prices | V1: DiscountPct | W1: Quantity | X1: GrossRevenue | Y1: CostofGoods | Z1: GrossProfit | AA1: MarginPct | AB1: MMM-YYYY | AC1: Quarter | AD1: Region Hierarchy | AE1: PriceBand | AF1: Month | AG1: Year | AH1: Percentile | AI1: New RequiredDate | AJ1: Discount Cap | AK1: UnitCost Inflation | AL1: Quantity Uplift | AM1: Margin% | AN1: Number of Orders | AO1: Avg Order Value | AP1: On Time%
A2: ORD-2023-723587 | B2: 44928 | C2: 44931 | D2: =IF(Table1[[#This Row],[RequiredDate]]<Table1[[#This Row],[OrderDate]],Table1[[#This Row],[RequiredDate]],Table1[[#This Row],[OrderDate]]) -> 44928 | E2: =IF(Table1[[#This Row],[RequiredDate]]>Table1[[#This Row],[OrderDate]],Table1[[#This Row],[RequiredDate]],Table1[[#This Row],[OrderDate]]) -> 44931 | F2: =Table1[[#This Row],[New RD]]-Table1[[#This Row],[new od]] -> 3 | G2: =IF(Table1[[#This Row],[RequiredDate]]<Table1[[#This Row],[OrderDate]], Table1[[#This Row],[OrderDate]]+7, Table1[[#This Row],[RequiredDate]]) -> 44931 | H2: =G2-B2 -> 3 | I2: =IF(Table1[[#This Row],[New LTD]]<=7,"Yes","No") -> Yes | K2: Americas | L2: Canada | M2: Toronto | N2: Corporate | O2: Distributor | P2: B. Chen | Q2: Laptops | R2: LAP-8555 | S2: 315.87 | T2: 591.68 | U2: =ABS(T2) -> 591.68 | V2: 0 | W2: 7 | X2: =U2*W2*(1-V2) -> 4141.76 | Y2: =S2*W2 -> 2211.09 | Z2: =X2-Y2 -> 1930.67 | AA2: =IF(X2=0, 0, Z2/ X2) -> 0.46614724 | AB2: =_xlfn.CONCAT(MONTH(B2),"-",YEAR(B2)) -> 1-2023 | AC2: ="Q"&ROUNDUP(MONTH(B2)/3,0)&"-"&YEAR(B2) -> Q1-2023 | AD2: =_xlfn.CONCAT(K2," →",L2," →",M2) -> Americas →Canada →Toronto | AE2: =IF(T2<=LowerCutOff,"Low", IF(T2<=HigherCutOff,"Medium","High")) -> Low | AF2: =TEXT(Table1[[#This Row],[OrderDate]],"MMM") -> Jan | AG2: =TEXT(Table1[[#This Row],[OrderDate]],"YYYY") -> 2023 | AH2: =_xlfn.PERCENTILE.INC(T:T,0.33) -> 816.0801 | AI2: =IF(Table1[[#This Row],[RequiredDate]]<Table1[[#This Row],[OrderDate]], Table1[[#This Row],[OrderDate]]+7, Table1[[#This Row],[RequiredDate]]) -> 44931 | AJ2: =IF(Dashboard!$D$3>'Staging Data'!V2,'Staging Data'!V2,Dashboard!D$3) -> 0 | AK2: =(100%+Dashboard!$D$4)*'Staging Data'!S2 -> 331.6635 | AL2: =(100%+Dashboard!$D$5)*'Staging Data'!W2 -> 8.05 | AM2: =(Z634/X634) -> 0.31120377 | AN2: =COUNTA(_xlfn.UNIQUE(A1:A633)) -> 632 | AO2: =(X634/AN2) -> 17292.477 | AP2: =COUNTIF(F2:F633, ">=7")/ COUNT(F2:F633) -> 0.74683544
A3: ORD-2023-689428 | B3: 44933 | C3: 44956 | D3: =IF(Table1[[#This Row],[RequiredDate]]<Table1[[#This Row],[OrderDate]],Table1[[#This Row],[RequiredDate]],Table1[[#This Row],[OrderDate]]) -> 44933 | F3: =Table1[[#This Row],[New RD]]-Table1[[#This Row],[new od]] -> -44933 | G3: =IF(Table1[[#This Row],[RequiredDate]]<Table1[[#This Row],[OrderDate]], Table1[[#This Row],[OrderDate]]+7, Table1[[#This Row],[RequiredDate]]) -> 44956 | H3: =G3-B3 -> 23 | I3: =IF(Table1[[#This Row],[New LTD]]<=7,"Yes","No") -> Yes | J3: =IF(V3>20%,"Yes","No") -> No | K3: Africa | L3: South Africa | M3: Cape Town | N3: Consumer | O3: Online | P3: A. Patel | Q3: Printers | R3: PRN-4787 | S3: 299.02 | T3: 724.7 | U3: =ABS(T3) -> 724.7 | V3: 0.14 | W3: 5 | X3: =U3*W3*(1-V3) -> 3116.21 | Y3: =S3*W3 -> 1495.1 | Z3: =X3-Y3 -> 1621.11 | AA3: =IF(X3=0, 0, Z3/ X3) -> 0.52021847 | AB3: =_xlfn.CONCAT(MONTH(B3),"-",YEAR(B3)) -> 1-2023 | AC3: ="Q"&ROUNDUP(MONTH(B3)/3,0)&"-"&YEAR(B3) -> Q1-2023 | AD3: =_xlfn.CONCAT(K3," →",L3," →",M3) -> Africa →South Africa →Cape Town | AE3: =IF(T3<=LowerCutOff,"Low", IF(T3<=HigherCutOff,"Medium","High")) -> Low | AF3: =TEXT(Table1[[#This Row],[OrderDate]],"MMM") -> Jan | AG3: =TEXT(Table1[[#This Row],[OrderDate]],"YYYY") -> 2023 | AH3: =_xlfn.PERCENTILE.INC(T:T, 0.66) -> 1619.115 | AI3: =IF(Table1[[#This Row],[RequiredDate]]<Table1[[#This Row],[OrderDate]], Table1[[#This Row],[OrderDate]]+7, Table1[[#This Row],[RequiredDate]]) -> 44956 | AJ3: =IF(Dashboard!$D$3>'Staging Data'!V3,'Staging Data'!V3,Dashboard!D$3) -> 0.14 | AK3: =(100%+Dashboard!$D$4)*'Staging Data'!S3 -> 313.971 | AL3: =(100%+Dashboard!$D$5)*'Staging Data'!W3 -> 5.75
A4: ORD-2023-884192 | B4: 44936 | C4: 44955 | D4: =IF(Table1[[#This Row],[RequiredDate]]<Table1[[#This Row],[OrderDate]],Table1[[#This Row],[RequiredDate]],Table1[[#This Row],[OrderDate]]) -> 44936 | E4: =IF(Table1[[#This Row],[RequiredDate]]>Table1[[#This Row],[OrderDate]],Table1[[#This Row],[RequiredDate]],Table1[[#This Row],[OrderDate]]) -> 44955 | F4: =Table1[[#This Row],[New RD]]-Table1[[#This Row],[new od]] -> 19 | G4: =IF(Table1[[#This Row],[RequiredDate]]<Table1[[#This Row],[OrderDate]], Table1[[#This Row],[OrderDate]]+7, Table1[[#This Row],[RequiredDate]]) -> 44955 | H4: =G4-B4 -> 19 | I4: =IF(Table1[[#This Row],[New LTD]]<=7,"Yes","No") -> No | J4: =IF(V4>20%,"Yes","No") -> No | K4: Europe | L4: France | M4: Lyon | N4: Non-Profit | O4: Direct | P4: D. Smith | Q4: Laptops | R4: LAP-4551 | S4: 401.66 | T4: 772.09 | U4: =ABS(T4) -> 772.09 | V4: 0.089 | W4: 14 | X4: =U4*W4*(1-V4) -> 9847.2359 | Y4: =S4*W4 -> 5623.24 | Z4: =X4-Y4 -> 4223.9959 | AA4: =IF(X4=0, 0, Z4/ X4) -> 0.42895244 | AB4: =_xlfn.CONCAT(MONTH(B4),"-",YEAR(B4)) -> 1-2023 | AC4: ="Q"&ROUNDUP(MONTH(B4)/3,0)&"-"&YEAR(B4) -> Q1-2023 | AD4: =_xlfn.CONCAT(K4," →",L4," →",M4) -> Europe →France →Lyon | AE4: =IF(T4<=LowerCutOff,"Low", IF(T4<=HigherCutOff,"Medium","High")) -> Low | AF4: =TEXT(Table1[[#This Row],[OrderDate]],"MMM") -> Jan | AG4: =TEXT(Table1[[#This Row],[OrderDate]],"YYYY") -> 2023 | AI4: =IF(Table1[[#This Row],[RequiredDate]]<Table1[[#This Row],[OrderDate]], Table1[[#This Row],[OrderDate]]+7, Table1[[#This Row],[RequiredDate]]) -> 44955 | AJ4: =IF(Dashboard!$D$3>'Staging Data'!V4,'Staging Data'!V4,Dashboard!D$3) -> 0.089 | AK4: =(100%+Dashboard!$D$4)*'Staging Data'!S4 -> 421.743 | AL4: =(100%+Dashboard!$D$5)*'Staging Data'!W4 -> 16.1
A5: ORD-2023-700699 | B5: 44938 | C5: 44952 | D5: =IF(Table1[[#This Row],[RequiredDate]]<Table1[[#This Row],[OrderDate]],Table1[[#This Row],[RequiredDate]],Table1[[#This Row],[OrderDate]]) -> 44938 | E5: =IF(Table1[[#This Row],[RequiredDate]]>Table1[[#This Row],[OrderDate]],Table1[[#This Row],[RequiredDate]],Table1[[#This Row],[OrderDate]]) -> 44952 | F5: =Table1[[#This Row],[New RD]]-Table1[[#This Row],[new od]] -> 14 | G5: =IF(Table1[[#This Row],[RequiredDate]]<Table1[[#This Row],[OrderDate]], Table1[[#This Row],[OrderDate]]+7, Table1[[#This Row],[RequiredDate]]) -> 44952 | H5: =G5-B5 -> 14 | I5: =IF(Table1[[#This Row],[New LTD]]<=7,"Yes","No") -> No | J5: =IF(V5>20%,"Yes","No") -> No | K5: Asia | L5: China | M5: Shenzhen | N5: Non-Profit | O5: Retail | P5: M. Rossi | Q5: Printers | R5: PRN-1641 | S5: 1083.09 | T5: 1425.87 | U5: =ABS(T5) -> 1425.87 | V5: 0 | W5: 8 | X5: =U5*W5*(1-V5) -> 11406.96 | Y5: =S5*W5 -> 8664.72 | Z5: =X5-Y5 -> 2742.24 | AA5: =IF(X5=0, 0, Z5/ X5) -> 0.2404006 | AB5: =_xlfn.CONCAT(MONTH(B5),"-",YEAR(B5)) -> 1-2023 | AC5: ="Q"&ROUNDUP(MONTH(B5)/3,0)&"-"&YEAR(B5) -> Q1-2023 | AD5: =_xlfn.CONCAT(K5," →",L5," →",M5) -> Asia →China →Shenzhen | AE5: =IF(T5<=LowerCutOff,"Low", IF(T5<=HigherCutOff,"Medium","High")) -> Medium | AF5: =TEXT(Table1[[#This Row],[OrderDate]],"MMM") -> Jan | AG5: =TEXT(Table1[[#This Row],[OrderDate]],"YYYY") -> 2023 | AI5: =IF(Table1[[#This Row],[RequiredDate]]<Table1[[#This Row],[OrderDate]], Table1[[#This Row],[OrderDate]]+7, Table1[[#This Row],[RequiredDate]]) -> 44952 | AJ5: =IF(Dashboard!$D$3>'Staging Data'!V5,'Staging Data'!V5,Dashboard!D$3) -> 0 | AK5: =(100%+Dashboard!$D$4)*'Staging Data'!S5 -> 1137.2445 | AL5: =(100%+Dashboard!$D$5)*'Staging Data'!W5 -> 9.2
A6: ORD-2023-382017 | B6: 44939 | C6: 44945 | D6: =IF(Table1[[#This Row],[RequiredDate]]<Table1[[#This Row],[OrderDate]],Table1[[#This Row],[RequiredDate]],Table1[[#This Row],[OrderDate]]) -> 44939 | E6: =IF(Table1[[#This Row],[RequiredDate]]>Table1[[#This Row],[OrderDate]],Table1[[#This Row],[RequiredDate]],Table1[[#This Row],[OrderDate]]) -> 44945 | F6: =Table1[[#This Row],[New RD]]-Table1[[#This Row],[new od]] -> 6 | G6: =IF(Table1[[#This Row],[RequiredDate]]<Table1[[#This Row],[OrderDate]], Table1[[#This Row],[OrderDate]]+7, Table1[[#This Row],[RequiredDate]]) -> 44945 | H6: =G6-B6 -> 6 | I6: =IF(Table1[[#This Row],[New LTD]]<=7,"Yes","No") -> Yes | J6: =IF(V6>20%,"Yes","No") -> No | K6: Americas | L6: USA | M6: Chicago | N6: Corporate | O6: Direct | P6: H. Kim | Q6: Phones | R6: PHN-3159 | S6: 833.57 | T6: 881.57 | U6: =ABS(T6) -> 881.57 | V6: 0.057 | W6: 18 | X6: =U6*W6*(1-V6) -> 14963.769 | Y6: =S6*W6 -> 15004.26 | Z6: =X6-Y6 -> -40.49082 | AA6: =IF(X6=0, 0, Z6/ X6) -> -0.0027059239 | AB6: =_xlfn.CONCAT(MONTH(B6),"-",YEAR(B6)) -> 1-2023 | AC6: ="Q"&ROUNDUP(MONTH(B6)/3,0)&"-"&YEAR(B6) -> Q1-2023 | AD6: =_xlfn.CONCAT(K6," →",L6," →",M6) -> Americas →USA →Chicago | AE6: =IF(T6<=LowerCutOff,"Low", IF(T6<=HigherCutOff,"Medium","High")) -> Medium | AF6: =TEXT(Table1[[#This Row],[OrderDate]],"MMM") -> Jan | AG6: =TEXT(Table1[[#This Row],[OrderDate]],"YYYY") -> 2023 | AI6: =IF(Table1[[#This Row],[RequiredDate]]<Table1[[#This Row],[OrderDate]], Table1[[#This Row],[OrderDate]]+7, Table1[[#This Row],[RequiredDate]]) -> 44945 | AJ6: =IF(Dashboard!$D$3>'Staging Data'!V6,'Staging Data'!V6,Dashboard!D$3) -> 0.057 | AK6: =(100%+Dashboard!$D$4)*'Staging Data'!S6 -> 875.2485 | AL6: =(100%+Dashboard!$D$5)*'Staging Data'!W6 -> 20.7
A7: ORD-2023-112666 | B7: 44941 | C7: 44939 | D7: =IF(Table1[[#This Row],[RequiredDate]]<Table1[[#This Row],[OrderDate]],Table1[[#This Row],[RequiredDate]],Table1[[#This Row],[OrderDate]]) -> 44939 | E7: =IF(Table1[[#This Row],[RequiredDate]]>Table1[[#This Row],[OrderDate]],Table1[[#This Row],[RequiredDate]],Table1[[#This Row],[OrderDate]]) -> 44941 | F7: =Table1[[#This Row],[New RD]]-Table1[[#This Row],[new od]] -> 2 | G7: =IF(Table1[[#This Row],[RequiredDate]]<Table1[[#This Row],[OrderDate]], Table1[[#This Row],[OrderDate]]+7, Table1[[#This Row],[RequiredDate]]) -> 44948 | H7: =G7-B7 -> 7 | I7: =IF(Table1[[#This Row],[New LTD]]<=7,"Yes","No") -> Yes | J7: =IF(V7>20%,"Yes","No") -> No | K7: Africa | L7: Nigeria | M7: Abuja | N7: Education | O7: Online | P7: O. Wang | Q7: Printers | R7: PRN-6276 | S7: 28.38 | T7: 47.22 | U7: =ABS(T7) -> 47.22 | V7: 0.194 | W7: 18 | X7: =U7*W7*(1-V7) -> 685.06776 | Y7: =S7*W7 -> 510.84 | Z7: =X7-Y7 -> 174.22776 | AA7: =IF(X7=0, 0, Z7/ X7) -> 0.25432194 | AB7: =_xlfn.CONCAT(MONTH(B7),"-",YEAR(B7)) -> 1-2023 | AC7: ="Q"&ROUNDUP(MONTH(B7)/3,0)&"-"&YEAR(B7) -> Q1-2023 | AD7: =_xlfn.CONCAT(K7," →",L7," →",M7) -> Africa →Nigeria →Abuja | AE7: =IF(T7<=LowerCutOff,"Low", IF(T7<=HigherCutOff,"Medium","High")) -> Low | AF7: =TEXT(Table1[[#This Row],[OrderDate]],"MMM") -> Jan | AG7: =TEXT(Table1[[#This Row],[OrderDate]],"YYYY") -> 2023 | AI7: =IF(Table1[[#This Row],[RequiredDate]]<Table1[[#This Row],[OrderDate]], Table1[[#This Row],[OrderDate]]+7, Table1[[#This Row],[RequiredDate]]) -> 44948 | AJ7: =IF(Dashboard!$D$3>'Staging Data'!V7,'Staging Data'!V7,Dashboard!D$3) -> 0.194 | AK7: =(100%+Dashboard!$D$4)*'Staging Data'!S7 -> 29.799 | AL7: =(100%+Dashboard!$D$5)*'Staging Data'!W7 -> 20.7
A8: ORD-2023-780206 | B8: 44945 | C8: 44960 | D8: =IF(Table1[[#This Row],[RequiredDate]]<Table1[[#This Row],[OrderDate]],Table1[[#This Row],[RequiredDate]],Table1[[#This Row],[OrderDate]]) -> 44945 | E8: =IF(Table1[[#This Row],[RequiredDate]]>Table1[[#This Row],[OrderDate]],Table1[[#This Row],[RequiredDate]],Table1[[#This Row],[OrderDate]]) -> 44960 | F8: =Table1[[#This Row],[New RD]]-Table1[[#This Row],[new od]] -> 15 | G8: =IF(Table1[[#This Row],[RequiredDate]]<Table1[[#This Row],[OrderDate]], Table1[[#This Row],[OrderDate]]+7, Table1[[#This Row],[RequiredDate]]) -> 44960 | H8: =G8-B8 -> 15 | I8: =IF(Table1[[#This Row],[New LTD]]<=7,"Yes","No") -> No | J8: =IF(V8>20%,"Yes","No") -> No | K8: Europe | L8: United Kingdom | M8: London | N8: Enterprise | O8: Distributor | P8: G. Dubois | Q8: Accessories | R8: ACC-3645 | S8: 873.06 | T8: 2101.55 | U8: =ABS(T8) -> 2101.55 | V8: 0.066 | W8: 10 | X8: =U8*W8*(1-V8) -> 19628.477 | Y8: =S8*W8 -> 8730.6 | Z8: =X8-Y8 -> 10897.877 | AA8: =IF(X8=0, 0, Z8/ X8) -> 0.55520747 | AB8: =_xlfn.CONCAT(MONTH(B8),"-",YEAR(B8)) -> 1-2023 | AC8: ="Q"&ROUNDUP(MONTH(B8)/3,0)&"-"&YEAR(B8) -> Q1-2023 | AD8: =_xlfn.CONCAT(K8," →",L8," →",M8) -> Europe →United Kingdom →London | AE8: =IF(T8<=LowerCutOff,"Low", IF(T8<=HigherCutOff,"Medium","High")) -> High | AF8: =TEXT(Table1[[#This Row],[OrderDate]],"MMM") -> Jan | AG8: =TEXT(Table1[[#This Row],[OrderDate]],"YYYY") -> 2023 | AI8: =IF(Table1[[#This Row],[RequiredDate]]<Table1[[#This Row],[OrderDate]], Table1[[#This Row],[OrderDate]]+7, Table1[[#This Row],[RequiredDate]]) -> 44960 | AJ8: =IF(Dashboard!$D$3>'Staging Data'!V8,'Staging Data'!V8,Dashboard!D$3) -> 0.066 | AK8: =(100%+Dashboard!$D$4)*'Staging Data'!S8 -> 916.713 | AL8: =(100%+Dashboard!$D$5)*'Staging Data'!W8 -> 11.5
A9: ORD-2023-586275 | B9: 44946 | C9: 44960 | D9: =IF(Table1[[#This Row],[RequiredDate]]<Table1[[#This Row],[OrderDate]],Table1[[#This Row],[RequiredDate]],Table1[[#This Row],[OrderDate]]) -> 44946 | E9: =IF(Table1[[#This Row],[RequiredDate]]>Table1[[#This Row],[OrderDate]],Table1[[#This Row],[RequiredDate]],Table1[[#This Row],[OrderDate]]) -> 44960 | F9: =Table1[[#This Row],[New RD]]-Table1[[#This Row],[new od]] -> 14 | G9: =IF(Table1[[#This Row],[RequiredDate]]<Table1[[#This Row],[OrderDate]], Table1[[#This Row],[OrderDate]]+7, Table1[[#This Row],[RequiredDate]]) -> 44960 | H9: =G9-B9 -> 14 | I9: =IF(Table1[[#This Row],[New LTD]]<=7,"Yes","No") -> No | J9: =IF(V9>20%,"Yes","No") -> Yes | K9: Africa | L9: Kenya | M9: Kisumu | N9: Corporate | O9: Retail | P9: M. Rossi | Q9: Networking | R9: NET-6036 | S9: 884.36 | T9: 1545.34 | U9: =ABS(T9) -> 1545.34 | V9: 0.243 | W9: 41 | X9: =U9*W9*(1-V9) -> 47962.718 | Y9: =S9*W9 -> 36258.76 | Z9: =X9-Y9 -> 11703.958 | AA9: =IF(X9=0, 0, Z9/ X9) -> 0.24402199 | AB9: =_xlfn.CONCAT(MONTH(B9),"-",YEAR(B9)) -> 1-2023 | AC9: ="Q"&ROUNDUP(MONTH(B9)/3,0)&"-"&YEAR(B9) -> Q1-2023 | AD9: =_xlfn.CONCAT(K9," →",L9," →",M9) -> Africa →Kenya →Kisumu | AE9: =IF(T9<=LowerCutOff,"Low", IF(T9<=HigherCutOff,"Medium","High")) -> Medium | AF9: =TEXT(Table1[[#This Row],[OrderDate]],"MMM") -> Jan | AG9: =TEXT(Table1[[#This Row],[OrderDate]],"YYYY") -> 2023 | AI9: =IF(Table1[[#This Row],[RequiredDate]]<Table1[[#This Row],[OrderDate]], Table1[[#This Row],[OrderDate]]+7, Table1[[#This Row],[RequiredDate]]) -> 44960 | AJ9: =IF(Dashboard!$D$3>'Staging Data'!V9,'Staging Data'!V9,Dashboard!D$3) -> 0.2 | AK9: =(100%+Dashboard!$D$4)*'Staging Data'!S9 -> 928.578 | AL9: =(100%+Dashboard!$D$5)*'Staging Data'!W9 -> 47.15
A10: ORD-2023-521818 | B10: 44948 | C10: 44956 | D10: =IF(Table1[[#This Row],[RequiredDate]]<Table1[[#This Row],[OrderDate]],Table1[[#This Row],[RequiredDate]],Table1[[#This Row],[OrderDate]]) -> 44948 | E10: =IF(Table1[[#This Row],[RequiredDate]]>Table1[[#This Row],[OrderDate]],Table1[[#This Row],[RequiredDate]],Table1[[#This Row],[OrderDate]]) -> 44956 | F10: =Table1[[#This Row],[New RD]]-Table1[[#This Row],[new od]] -> 8 | G10: =IF(Table1[[#This Row],[RequiredDate]]<Table1[[#This Row],[OrderDate]], Table1[[#This Row],[OrderDate]]+7, Table1[[#This Row],[RequiredDate]]) -> 44956 | H10: =G10-B10 -> 8 | I10: =IF(Table1[[#This Row],[New LTD]]<=7,"Yes","No") -> No | J10: =IF(V10>20%,"Yes","No") -> No | K10: Americas | L10: USA | M10: San Francisco | N10: Small Business | O10: Online | P10: A. Patel | Q10: Networking | R10: NET-4155 | S10: 413.52 | T10: 1004.34 | U10: =ABS(T10) -> 1004.34 | V10: 0.111 | W10: 18 | X10: =U10*W10*(1-V10) -> 16071.449 | Y10: =S10*W10 -> 7443.36 | Z10: =X10-Y10 -> 8628.0887 | AA10: =IF(X10=0, 0, Z10/ X10) -> 0.53685818 | AB10: =_xlfn.CONCAT(MONTH(B10),"-",YEAR(B10)) -> 1-2023 | AC10: ="Q"&ROUNDUP(MONTH(B10)/3,0)&"-"&YEAR(B10) -> Q1-2023 | AD10: =_xlfn.CONCAT(K10," →",L10," →",M10) -> Americas →USA →San Francisco | AE10: =IF(T10<=LowerCutOff,"Low", IF(T10<=HigherCutOff,"Medium","High")) -> Medium | AF10: =TEXT(Table1[[#This Row],[OrderDate]],"MMM") -> Jan | AG10: =TEXT(Table1[[#This Row],[OrderDate]],"YYYY") -> 2023 | AI10: =IF(Table1[[#This Row],[RequiredDate]]<Table1[[#This Row],[OrderDate]], Table1[[#This Row],[OrderDate]]+7, Table1[[#This Row],[RequiredDate]]) -> 44956 | AJ10: =IF(Dashboard!$D$3>'Staging Data'!V10,'Staging Data'!V10,Dashboard!D$3) -> 0.111 | AK10: =(100%+Dashboard!$D$4)*'Staging Data'!S10 -> 434.196 | AL10: =(100%+Dashboard!$D$5)*'Staging Data'!W10 -> 20.7
A11: ORD-2023-613317 | B11: 44948 | C11: 44947 | D11: =IF(Table1[[#This Row],[RequiredDate]]<Table1[[#This Row],[OrderDate]],Table1[[#This Row],[RequiredDate]],Table1[[#This Row],[OrderDate]]) -> 44947 | E11: =IF(Table1[[#This Row],[RequiredDate]]>Table1[[#This Row],[OrderDate]],Table1[[#This Row],[RequiredDate]],Table1[[#This Row],[OrderDate]]) -> 44948 | F11: =Table1[[#This Row],[New RD]]-Table1[[#This Row],[new od]] -> 1 | G11: =IF(Table1[[#This Row],[RequiredDate]]<Table1[[#This Row],[OrderDate]], Table1[[#This Row],[OrderDate]]+7, Table1[[#This Row],[RequiredDate]]) -> 44955 | H11: =G11-B11 -> 7 | I11: =IF(Table1[[#This Row],[New LTD]]<=7,"Yes","No") -> Yes | J11: =IF(V11>20%,"Yes","No") -> No | K11: Europe | L11: Germany | M11: Munich | N11: Corporate | O11: Direct | P11: F. Müller | Q11: Monitors | R11: MON-2537 | S11: 150.86 | T11: 346.96 | U11: =ABS(T11) -> 346.96 | V11: 0.196 | W11: 8 | X11: =U11*W11*(1-V11) -> 2231.6467 | Y11: =S11*W11 -> 1206.88 | Z11: =X11-Y11 -> 1024.7667 | AA11: =IF(X11=0, 0, Z11/ X11) -> 0.45919756 | AB11: =_xlfn.CONCAT(MONTH(B11),"-",YEAR(B11)) -> 1-2023 | AC11: ="Q"&ROUNDUP(MONTH(B11)/3,0)&"-"&YEAR(B11) -> Q1-2023 | AD11: =_xlfn.CONCAT(K11," →",L11," →",M11) -> Europe →Germany →Munich | AE11: =IF(T11<=LowerCutOff,"Low", IF(T11<=HigherCutOff,"Medium","High")) -> Low | AF11: =TEXT(Table1[[#This Row],[OrderDate]],"MMM") -> Jan | AG11: =TEXT(Table1[[#This Row],[OrderDate]],"YYYY") -> 2023 | AI11: =IF(Table1[[#This Row],[RequiredDate]]<Table1[[#This Row],[OrderDate]], Table1[[#This Row],[OrderDate]]+7, Table1[[#This Row],[RequiredDate]]) -> 44955 | AJ11: =IF(Dashboard!$D$3>'Staging Data'!V11,'Staging Data'!V11,Dashboard!D$3) -> 0.196 | AK11: =(100%+Dashboard!$D$4)*'Staging Data'!S11 -> 158.403 | AL11: =(100%+Dashboard!$D$5)*'Staging Data'!W11 -> 9.2
A12: ORD-2023-811823 | B12: 44952 | C12: 44972 | D12: =IF(Table1[[#This Row],[RequiredDate]]<Table1[[#This Row],[OrderDate]],Table1[[#This Row],[RequiredDate]],Table1[[#This Row],[OrderDate]]) -> 44952 | E12: =IF(Table1[[#This Row],[RequiredDate]]>Table1[[#This Row],[OrderDate]],Table1[[#This Row],[RequiredDate]],Table1[[#This Row],[OrderDate]]) -> 44972 | F12: =Table1[[#This Row],[New RD]]-Table1[[#This Row],[new od]] -> 20 | G12: =IF(Table1[[#This Row],[RequiredDate]]<Table1[[#This Row],[OrderDate]], Table1[[#This Row],[OrderDate]]+7, Table1[[#This Row],[RequiredDate]]) -> 44972 | H12: =G12-B12 -> 20 | I12: =IF(Table1[[#This Row],[New LTD]]<=7,"Yes","No") -> No | J12: =IF(V12>20%,"Yes","No") -> No | K12: Europe | L12: Germany | M12: Berlin | N12: Small Business | O12: Online | P12: O. Wang | Q12: Networking | R12: NET-8787 | S12: 492.62 | T12: 366.7 | U12: =ABS(T12) -> 366.7 | V12: 0.089 | W12: 10 | X12: =U12*W12*(1-V12) -> 3340.637 | Y12: =S12*W12 -> 4926.2 | Z12: =X12-Y12 -> -1585.563 | AA12: =IF(X12=0, 0, Z12/ X12) -> -0.47462894 | AB12: =_xlfn.CONCAT(MONTH(B12),"-",YEAR(B12)) -> 1-2023 | AC12: ="Q"&ROUNDUP(MONTH(B12)/3,0)&"-"&YEAR(B12) -> Q1-2023 | AD12: =_xlfn.CONCAT(K12," →",L12," →",M12) -> Europe →Germany →Berlin | AE12: =IF(T12<=LowerCutOff,"Low", IF(T12<=HigherCutOff,"Medium","High")) -> Low | AF12: =TEXT(Table1[[#This Row],[OrderDate]],"MMM") -> Jan | AG12: =TEXT(Table1[[#This Row],[OrderDate]],"YYYY") -> 2023 | AI12: =IF(Table1[[#This Row],[RequiredDate]]<Table1[[#This Row],[OrderDate]], Table1[[#This Row],[OrderDate]]+7, Table1[[#This Row],[RequiredDate]]) -> 44972 | AJ12: =IF(Dashboard!$D$3>'Staging Data'!V12,'Staging Data'!V12,Dashboard!D$3) -> 0.089 | AK12: =(100%+Dashboard!$D$4)*'Staging Data'!S12 -> 517.251 | AL12: =(100%+Dashboard!$D$5)*'Staging Data'!W12 -> 11.5
A13: ORD-2023-430904 | B13: 44953 | C13: 44957 | D13: =IF(Table1[[#This Row],[RequiredDate]]<Table1[[#This Row],[OrderDate]],Table1[[#This Row],[RequiredDate]],Table1[[#This Row],[OrderDate]]) -> 44953 | E13: =IF(Table1[[#This Row],[RequiredDate]]>Table1[[#This Row],[OrderDate]],Table1[[#This Row],[RequiredDate]],Table1[[#This Row],[OrderDate]]) -> 44957 | F13: =Table1[[#This Row],[New RD]]-Table1[[#This Row],[new od]] -> 4 | G13: =IF(Table1[[#This Row],[RequiredDate]]<Table1[[#This Row],[OrderDate]], Table1[[#This Row],[OrderDate]]+7, Table1[[#This Row],[RequiredDate]]) -> 44957 | H13: =G13-B13 -> 4 | I13: =IF(Table1[[#This Row],[New LTD]]<=7,"Yes","No") -> Yes | J13: =IF(V13>20%,"Yes","No") -> Yes | K13: Europe | L13: United Kingdom | M13: Manchester | N13: Enterprise | O13: Online | P13: N. Brown | Q13: Laptops | R13: LAP-9782 | S13: 941.2 | T13: 668.02 | U13: =ABS(T13) -> 668.02 | V13: 0.22 | W13: 16 | X13: =U13*W13*(1-V13) -> 8336.8896 | Y13: =S13*W13 -> 15059.2 | Z13: =X13-Y13 -> -6722.3104 | AA13: =IF(X13=0, 0, Z13/ X13) -> -0.80633314 | AB13: =_xlfn.CONCAT(MONTH(B13),"-",YEAR(B13)) -> 1-2023 | AC13: ="Q"&ROUNDUP(MONTH(B13)/3,0)&"-"&YEAR(B13) -> Q1-2023 | AD13: =_xlfn.CONCAT(K13," →",L13," →",M13) -> Europe →United Kingdom →Manchester | AE13: =IF(T13<=LowerCutOff,"Low", IF(T13<=HigherCutOff,"Medium","High")) -> Low | AF13: =TEXT(Table1[[#This Row],[OrderDate]],"MMM") -> Jan | AG13: =TEXT(Table1[[#This Row],[OrderDate]],"YYYY") -> 2023 | AI13: =IF(Table1[[#This Row],[RequiredDate]]<Table1[[#This Row],[OrderDate]], Table1[[#This Row],[OrderDate]]+7, Table1[[#This Row],[RequiredDate]]) -> 44957 | AJ13: =IF(Dashboard!$D$3>'Staging Data'!V13,'Staging Data'!V13,Dashboard!D$3) -> 0.2 | AK13: =(100%+Dashboard!$D$4)*'Staging Data'!S13 -> 988.26 | AL13: =(100%+Dashboard!$D$5)*'Staging Data'!W13 -> 18.4
A14: ORD-2023-521818 | B14: 44955 | C14: 44985 | D14: =IF(Table1[[#This Row],[RequiredDate]]<Table1[[#This Row],[OrderDate]],Table1[[#This Row],[RequiredDate]],Table1[[#This Row],[OrderDate]]) -> 44955 | E14: =IF(Table1[[#This Row],[RequiredDate]]>Table1[[#This Row],[OrderDate]],Table1[[#This Row],[RequiredDate]],Table1[[#This Row],[OrderDate]]) -> 44985 | F14: =Table1[[#This Row],[New RD]]-Table1[[#This Row],[new od]] -> 30 | G14: =IF(Table1[[#This Row],[RequiredDate]]<Table1[[#This Row],[OrderDate]], Table1[[#This Row],[OrderDate]]+7, Table1[[#This Row],[RequiredDate]]) -> 44985 | H14: =G14-B14 -> 30 | I14: =IF(Table1[[#This Row],[New LTD]]<=7,"Yes","No") -> No | J14: =IF(V14>20%,"Yes","No") -> Yes | K14: Asia | L14: India | M14: Bengaluru | N14: Non-Profit | O14: Retail | P14: B. Chen | Q14: Accessories | R14: ACC-4631 | S14: 1262.1 | T14: 1395.53 | U14: =ABS(T14) -> 1395.53 | V14: 0.233 | W14: 25 | X14: =U14*W14*(1-V14) -> 26759.288 | Y14: =S14*W14 -> 31552.5 | Z14: =X14-Y14 -> -4793.2122 | AA14: =IF(X14=0, 0, Z14/ X14) -> -0.17912331 | AB14: =_xlfn.CONCAT(MONTH(B14),"-",YEAR(B14)) -> 1-2023 | AC14: ="Q"&ROUNDUP(MONTH(B14)/3,0)&"-"&YEAR(B14) -> Q1-2023 | AD14: =_xlfn.CONCAT(K14," →",L14," →",M14) -> Asia →India →Bengaluru | AE14: =IF(T14<=LowerCutOff,"Low", IF(T14<=HigherCutOff,"Medium","High")) -> Medium | AF14: =TEXT(Table1[[#This Row],[OrderDate]],"MMM") -> Jan | AG14: =TEXT(Table1[[#This Row],[OrderDate]],"YYYY") -> 2023 | AI14: =IF(Table1[[#This Row],[RequiredDate]]<Table1[[#This Row],[OrderDate]], Table1[[#This Row],[OrderDate]]+7, Table1[[#This Row],[RequiredDate]]) -> 44985 | AJ14: =IF(Dashboard!$D$3>'Staging Data'!V14,'Staging Data'!V14,Dashboard!D$3) -> 0.2 | AK14: =(100%+Dashboard!$D$4)*'Staging Data'!S14 -> 1325.205 | AL14: =(100%+Dashboard!$D$5)*'Staging Data'!W14 -> 28.75
A15: ORD-2023-856322 | B15: 44955 | C15: 44963 | D15: =IF(Table1[[#This Row],[RequiredDate]]<Table1[[#This Row],[OrderDate]],Table1[[#This Row],[RequiredDate]],Table1[[#This Row],[OrderDate]]) -> 44955 | E15: =IF(Table1[[#This Row],[RequiredDate]]>Table1[[#This Row],[OrderDate]],Table1[[#This Row],[RequiredDate]],Table1[[#This Row],[OrderDate]]) -> 44963 | F15: =Table1[[#This Row],[New RD]]-Table1[[#This Row],[new od]] -> 8 | G15: =IF(Table1[[#This Row],[RequiredDate]]<Table1[[#This Row],[OrderDate]], Table1[[#This Row],[OrderDate]]+7, Table1[[#This Row],[RequiredDate]]) -> 44963 | H15: =G15-B15 -> 8 | I15: =IF(Table1[[#This Row],[New LTD]]<=7,"Yes","No") -> No | J15: =IF(V15>20%,"Yes","No") -> Yes | K15: Americas | L15: Brazil | M15: Brasília | N15: Corporate | O15: Marketplace | P15: D. Smith | Q15: Monitors | R15: MON-7207 | S15: 41.84 | T15: 86.2 | U15: =ABS(T15) -> 86.2 | V15: 0.226 | W15: 27 | X15: =U15*W15*(1-V15) -> 1801.4076 | Y15: =S15*W15 -> 1129.68 | Z15: =X15-Y15 -> 671.7276 | AA15: =IF(X15=0, 0, Z15/ X15) -> 0.3728904 | AB15: =_xlfn.CONCAT(MONTH(B15),"-",YEAR(B15)) -> 1-2023 | AC15: ="Q"&ROUNDUP(MONTH(B15)/3,0)&"-"&YEAR(B15) -> Q1-2023 | AD15: =_xlfn.CONCAT(K15," →",L15," →",M15) -> Americas →Brazil →Brasília | AE15: =IF(T15<=LowerCutOff,"Low", IF(T15<=HigherCutOff,"Medium","High")) -> Low | AF15: =TEXT(Table1[[#This Row],[OrderDate]],"MMM") -> Jan | AG15: =TEXT(Table1[[#This Row],[OrderDate]],"YYYY") -> 2023 | AI15: =IF(Table1[[#This Row],[RequiredDate]]<Table1[[#This Row],[OrderDate]], Table1[[#This Row],[OrderDate]]+7, Table1[[#This Row],[RequiredDate]]) -> 44963 | AJ15: =IF(Dashboard!$D$3>'Staging Data'!V15,'Staging Data'!V15,Dashboard!D$3) -> 0.2 | AK15: =(100%+Dashboard!$D$4)*'Staging Data'!S15 -> 43.932 | AL15: =(100%+Dashboard!$D$5)*'Staging Data'!W15 -> 31.05
... A280: ORD-2024-906395 | B280: 45361 | C280: 45391 | D280: =IF(Table1[[#This Row],[RequiredDate]]<Table1[[#This Row],[OrderDate]],Table1[[#This Row],[RequiredDate]],Table1[[#This Row],[OrderDate]]) -> 45361 | E280: =IF(Table1[[#This Row],[RequiredDate]]>Table1[[#This Row],[OrderDate]],Table1[[#This Row],[RequiredDate]],Table1[[#This Row],[OrderDate]]) -> 45391 | F280: =Table1[[#This Row],[New RD]]-Table1[[#This Row],[new od]] -> 30 | G280: =IF(Table1[[#This Row],[RequiredDate]]<Table1[[#This Row],[OrderDate]], Table1[[#This Row],[OrderDate]]+7, Table1[[#This Row],[RequiredDate]]) -> 45391 | H280: =G280-B280 -> 30 | I280: =IF(Table1[[#This Row],[New LTD]]<=7,"Yes","No") -> No | J280: =IF(V280>20%,"Yes","No") -> No | K280: Europe | L280: France | M280: Lyon | N280: Corporate | O280: Direct | P280: I. Johnson | Q280: Components | R280: CMP-8002 | S280: 1176.56 | T280: 1911.89 | U280: =ABS(T280) -> 1911.89 | V280: 0.119 | W280: 20 | X280: =U280*W280*(1-V280) -> 33687.502 | Y280: =S280*W280 -> 23531.2 | Z280: =X280-Y280 -> 10156.302 | AA280: =IF(X280=0, 0, Z280/ X280) -> 0.30148575 | AB280: =_xlfn.CONCAT(MONTH(B280),"-",YEAR(B280)) -> 3-2024 | AC280: ="Q"&ROUNDUP(MONTH(B280)/3,0)&"-"&YEAR(B280) -> Q1-2024 | AD280: =_xlfn.CONCAT(K280," →",L280," →",M280) -> Europe →France →Lyon | AE280: =IF(T280<=LowerCutOff,"Low", IF(T280<=HigherCutOff,"Medium","High")) -> High | AF280: =TEXT(Table1[[#This Row],[OrderDate]],"MMM") -> Mar | AG280: =TEXT(Table1[[#This Row],[OrderDate]],"YYYY") -> 2024 | AI280: =IF(Table1[[#This Row],[RequiredDate]]<Table1[[#This Row],[OrderDate]], Table1[[#This Row],[OrderDate]]+7, Table1[[#This Row],[RequiredDate]]) -> 45391 | AJ280: =IF(Dashboard!$D$3>'Staging Data'!V280,'Staging Data'!V280,Dashboard!D$3) -> 0.119 | AK280: =(100%+Dashboard!$D$4)*'Staging Data'!S280 -> 1235.388 | AL280: =(100%+Dashboard!$D$5)*'Staging Data'!W280 -> 23
A281: ORD-2024-275203 | B281: 45362 | C281: 45388 | D281: =IF(Table1[[#This Row],[RequiredDate]]<Table1[[#This Row],[OrderDate]],Table1[[#This Row],[RequiredDate]],Table1[[#This Row],[OrderDate]]) -> 45362 | E281: =IF(Table1[[#This Row],[RequiredDate]]>Table1[[#This Row],[OrderDate]],Table1[[#This Row],[RequiredDate]],Table1[[#This Row],[OrderDate]]) -> 45388 | F281: =Table1[[#This Row],[New RD]]-Table1[[#This Row],[new od]] -> 26 | G281: =IF(Table1[[#This Row],[RequiredDate]]<Table1[[#This Row],[OrderDate]], Table1[[#This Row],[OrderDate]]+7, Table1[[#This Row],[RequiredDate]]) -> 45388 | H281: =G281-B281 -> 26 | I281: =IF(Table1[[#This Row],[New LTD]]<=7,"Yes","No") -> No | J281: =IF(V281>20%,"Yes","No") -> No | K281: Africa | L281: Kenya | M281: Kisumu | N281: Corporate | O281: Retail | P281: C. Otieno | Q281: Components | R281: CMP-8270 | S281: 279.24 | T281: 608.9 | U281: =ABS(T281) -> 608.9 | V281: 0.112 | W281: 9 | X281: =U281*W281*(1-V281) -> 4866.3288 | Y281: =S281*W281 -> 2513.16 | Z281: =X281-Y281 -> 2353.1688 | AA281: =IF(X281=0, 0, Z281/ X281) -> 0.48356141 | AB281: =_xlfn.CONCAT(MONTH(B281),"-",YEAR(B281)) -> 3-2024 | AC281: ="Q"&ROUNDUP(MONTH(B281)/3,0)&"-"&YEAR(B281) -> Q1-2024 | AD281: =_xlfn.CONCAT(K281," →",L281," →",M281) -> Africa →Kenya →Kisumu | AF281: =TEXT(Table1[[#This Row],[OrderDate]],"MMM") -> Mar | AG281: =TEXT(Table1[[#This Row],[OrderDate]],"YYYY") -> 2024 | AI281: =IF(Table1[[#This Row],[RequiredDate]]<Table1[[#This Row],[OrderDate]], Table1[[#This Row],[OrderDate]]+7, Table1[[#This Row],[RequiredDate]]) -> 45388 | AJ281: =IF(Dashboard!$D$3>'Staging Data'!V281,'Staging Data'!V281,Dashboard!D$3) -> 0.112 | AK281: =(100%+Dashboard!$D$4)*'Staging Data'!S281 -> 293.202 | AL281: =(100%+Dashboard!$D$5)*'Staging Data'!W281 -> 10.35
A282: ORD-2024-687073 | B282: 45362 | C282: 45380 | D282: =IF(Table1[[#This Row],[RequiredDate]]<Table1[[#This Row],[OrderDate]],Table1[[#This Row],[RequiredDate]],Table1[[#This Row],[OrderDate]]) -> 45362 | E282: =IF(Table1[[#This Row],[RequiredDate]]>Table1[[#This Row],[OrderDate]],Table1[[#This Row],[RequiredDate]],Table1[[#This Row],[OrderDate]]) -> 45380 | F282: =Table1[[#This Row],[New RD]]-Table1[[#This Row],[new od]] -> 18 | G282: =IF(Table1[[#This Row],[RequiredDate]]<Table1[[#This Row],[OrderDate]], Table1[[#This Row],[OrderDate]]+7, Table1[[#This Row],[RequiredDate]]) -> 45380 | H282: =G282-B282 -> 18 | I282: =IF(Table1[[#This Row],[New LTD]]<=7,"Yes","No") -> No | J282: =IF(V282>20%,"Yes","No") -> Yes | K282: Americas | L282: USA | M282: New York | N282: Corporate | O282: Retail | P282: M. Rossi | Q282: Monitors | R282: MON-7099 | S282: 710.98 | T282: 1481.45 | U282: =ABS(T282) -> 1481.45 | V282: 0.211 | W282: 9 | X282: =U282*W282*(1-V282) -> 10519.776 | Y282: =S282*W282 -> 6398.82 | Z282: =X282-Y282 -> 4120.9565 | AA282: =IF(X282=0, 0, Z282/ X282) -> 0.39173422 | AB282: =_xlfn.CONCAT(MONTH(B282),"-",YEAR(B282)) -> 3-2024 | AC282: ="Q"&ROUNDUP(MONTH(B282)/3,0)&"-"&YEAR(B282) -> Q1-2024 | AD282: =_xlfn.CONCAT(K282," →",L282," →",M282) -> Americas →USA →New York | AE282: =IF(T282<=LowerCutOff,"Low", IF(T282<=HigherCutOff,"Medium","High")) -> Medium | AF282: =TEXT(Table1[[#This Row],[OrderDate]],"MMM") -> Mar | AG282: =TEXT(Table1[[#This Row],[OrderDate]],"YYYY") -> 2024 | AI282: =IF(Table1[[#This Row],[RequiredDate]]<Table1[[#This Row],[OrderDate]], Table1[[#This Row],[OrderDate]]+7, Table1[[#This Row],[RequiredDate]]) -> 45380 | AJ282: =IF(Dashboard!$D$3>'Staging Data'!V282,'Staging Data'!V282,Dashboard!D$3) -> 0.2 | AK282: =(100%+Dashboard!$D$4)*'Staging Data'!S282 -> 746.529 | AL282: =(100%+Dashboard!$D$5)*'Staging Data'!W282 -> 10.35
A283: ORD-2024-243988 | B283: 45364 | C283: 45388 | D283: =IF(Table1[[#This Row],[RequiredDate]]<Table1[[#This Row],[OrderDate]],Table1[[#This Row],[RequiredDate]],Table1[[#This Row],[OrderDate]]) -> 45364 | E283: =IF(Table1[[#This Row],[RequiredDate]]>Table1[[#This Row],[OrderDate]],Table1[[#This Row],[RequiredDate]],Table1[[#This Row],[OrderDate]]) -> 45388 | F283: =Table1[[#This Row],[New RD]]-Table1[[#This Row],[new od]] -> 24 | G283: =IF(Table1[[#This Row],[RequiredDate]]<Table1[[#This Row],[OrderDate]], Table1[[#This Row],[OrderDate]]+7, Table1[[#This Row],[RequiredDate]]) -> 45388 | H283: =G283-B283 -> 24 | I283: =IF(Table1[[#This Row],[New LTD]]<=7,"Yes","No") -> No | J283: =IF(V283>20%,"Yes","No") -> No | K283: Africa | L283: Nigeria | M283: Abuja | N283: Consumer | O283: Distributor | P283: L. Okafor | Q283: Components | R283: CMP-9001 | S283: 1232.78 | T283: 1731.75 | U283: =ABS(T283) -> 1731.75 | V283: 0.093 | W283: 16 | X283: =U283*W283*(1-V283) -> 25131.156 | Y283: =S283*W283 -> 19724.48 | Z283: =X283-Y283 -> 5406.676 | AA283: =IF(X283=0, 0, Z283/ X283) -> 0.21513837 | AB283: =_xlfn.CONCAT(MONTH(B283),"-",YEAR(B283)) -> 3-2024 | AC283: ="Q"&ROUNDUP(MONTH(B283)/3,0)&"-"&YEAR(B283) -> Q1-2024 | AD283: =_xlfn.CONCAT(K283," →",L283," →",M283) -> Africa →Nigeria →Abuja | AE283: =IF(T283<=LowerCutOff,"Low", IF(T283<=HigherCutOff,"Medium","High")) -> High | AF283: =TEXT(Table1[[#This Row],[OrderDate]],"MMM") -> Mar | AG283: =TEXT(Table1[[#This Row],[OrderDate]],"YYYY") -> 2024 | AI283: =IF(Table1[[#This Row],[RequiredDate]]<Table1[[#This Row],[OrderDate]], Table1[[#This Row],[OrderDate]]+7, Table1[[#This Row],[RequiredDate]]) -> 45388 | AJ283: =IF(Dashboard!$D$3>'Staging Data'!V283,'Staging Data'!V283,Dashboard!D$3) -> 0.093 | AK283: =(100%+Dashboard!$D$4)*'Staging Data'!S283 -> 1294.419 | AL283: =(100%+Dashboard!$D$5)*'Staging Data'!W283 -> 18.4
A284: ORD-2024-220234 | B284: 45366 | C284: 45391 | D284: =IF(Table1[[#This Row],[RequiredDate]]<Table1[[#This Row],[OrderDate]],Table1[[#This Row],[RequiredDate]],Table1[[#This Row],[OrderDate]]) -> 45366 | E284: =IF(Table1[[#This Row],[RequiredDate]]>Table1[[#This Row],[OrderDate]],Table1[[#This Row],[RequiredDate]],Table1[[#This Row],[OrderDate]]) -> 45391 | F284: =Table1[[#This Row],[New RD]]-Table1[[#This Row],[new od]] -> 25 | G284: =IF(Table1[[#This Row],[RequiredDate]]<Table1[[#This Row],[OrderDate]], Table1[[#This Row],[OrderDate]]+7, Table1[[#This Row],[RequiredDate]]) -> 45391 | H284: =G284-B284 -> 25 | I284: =IF(Table1[[#This Row],[New LTD]]<=7,"Yes","No") -> No | J284: =IF(V284>20%,"Yes","No") -> Yes | K284: Americas | L284: Canada | M284: Vancouver | N284: Consumer | O284: Online | P284: F. Müller | Q284: Monitors | R284: MON-4361 | S284: 648.64 | T284: 815.19 | U284: =ABS(T284) -> 815.19 | V284: 0.225 | W284: 28 | X284: =U284*W284*(1-V284) -> 17689.623 | Y284: =S284*W284 -> 18161.92 | Z284: =X284-Y284 -> -472.297 | AA284: =IF(X284=0, 0, Z284/ X284) -> -0.026699099 | AB284: =_xlfn.CONCAT(MONTH(B284),"-",YEAR(B284)) -> 3-2024 | AC284: ="Q"&ROUNDUP(MONTH(B284)/3,0)&"-"&YEAR(B284) -> Q1-2024 | AD284: =_xlfn.CONCAT(K284," →",L284," →",M284) -> Americas →Canada →Vancouver | AE284: =IF(T284<=LowerCutOff,"Low", IF(T284<=HigherCutOff,"Medium","High")) -> Low | AF284: =TEXT(Table1[[#This Row],[OrderDate]],"MMM") -> Mar | AG284: =TEXT(Table1[[#This Row],[OrderDate]],"YYYY") -> 2024 | AI284: =IF(Table1[[#This Row],[RequiredDate]]<Table1[[#This Row],[OrderDate]], Table1[[#This Row],[OrderDate]]+7, Table1[[#This Row],[RequiredDate]]) -> 45391 | AJ284: =IF(Dashboard!$D$3>'Staging Data'!V284,'Staging Data'!V284,Dashboard!D$3) -> 0.2 | AK284: =(100%+Dashboard!$D$4)*'Staging Data'!S284 -> 681.072 | AL284: =(100%+Dashboard!$D$5)*'Staging Data'!W284 -> 32.2
A285: ORD-2024-834983 | B285: 45367 | C285: 45395 | D285: =IF(Table1[[#This Row],[RequiredDate]]<Table1[[#This Row],[OrderDate]],Table1[[#This Row],[RequiredDate]],Table1[[#This Row],[OrderDate]]) -> 45367 | E285: =IF(Table1[[#This Row],[RequiredDate]]>Table1[[#This Row],[OrderDate]],Table1[[#This Row],[RequiredDate]],Table1[[#This Row],[OrderDate]]) -> 45395 | F285: =Table1[[#This Row],[New RD]]-Table1[[#This Row],[new od]] -> 28 | G285: =IF(Table1[[#This Row],[RequiredDate]]<Table1[[#This Row],[OrderDate]], Table1[[#This Row],[OrderDate]]+7, Table1[[#This Row],[RequiredDate]]) -> 45395 | H285: =G285-B285 -> 28 | I285: =IF(Table1[[#This Row],[New LTD]]<=7,"Yes","No") -> No | J285: =IF(V285>20%,"Yes","No") -> No | K285: Europe | L285: France | M285: Paris | N285: Small Business | O285: Online | P285: K. Singh | Q285: Printers | R285: PRN-8758 | S285: 287.61 | T285: 628.54 | U285: =ABS(T285) -> 628.54 | V285: 0.135 | W285: 21 | X285: =U285*W285*(1-V285) -> 11417.429 | Y285: =S285*W285 -> 6039.81 | Z285: =X285-Y285 -> 5377.6191 | AA285: =IF(X285=0, 0, Z285/ X285) -> 0.47100088 | AB285: =_xlfn.CONCAT(MONTH(B285),"-",YEAR(B285)) -> 3-2024 | AC285: ="Q"&ROUNDUP(MONTH(B285)/3,0)&"-"&YEAR(B285) -> Q1-2024 | AD285: =_xlfn.CONCAT(K285," →",L285," →",M285) -> Europe →France →Paris | AE285: =IF(T285<=LowerCutOff,"Low", IF(T285<=HigherCutOff,"Medium","High")) -> Low | AF285: =TEXT(Table1[[#This Row],[OrderDate]],"MMM") -> Mar | AG285: =TEXT(Table1[[#This Row],[OrderDate]],"YYYY") -> 2024 | AI285: =IF(Table1[[#This Row],[RequiredDate]]<Table1[[#This Row],[OrderDate]], Table1[[#This Row],[OrderDate]]+7, Table1[[#This Row],[RequiredDate]]) -> 45395 | AJ285: =IF(Dashboard!$D$3>'Staging Data'!V285,'Staging Data'!V285,Dashboard!D$3) -> 0.135 | AK285: =(100%+Dashboard!$D$4)*'Staging Data'!S285 -> 301.9905 | AL285: =(100%+Dashboard!$D$5)*'Staging Data'!W285 -> 24.15
A286: ORD-2024-287210 | B286: 45369 | C286: 45372 | D286: =IF(Table1[[#This Row],[RequiredDate]]<Table1[[#This Row],[OrderDate]],Table1[[#This Row],[RequiredDate]],Table1[[#This Row],[OrderDate]]) -> 45369 | E286: =IF(Table1[[#This Row],[RequiredDate]]>Table1[[#This Row],[OrderDate]],Table1[[#This Row],[RequiredDate]],Table1[[#This Row],[OrderDate]]) -> 45372 | F286: =Table1[[#This Row],[New RD]]-Table1[[#This Row],[new od]] -> 3 | G286: =IF(Table1[[#This Row],[RequiredDate]]<Table1[[#This Row],[OrderDate]], Table1[[#This Row],[OrderDate]]+7, Table1[[#This Row],[RequiredDate]]) -> 45372 | H286: =G286-B286 -> 3 | I286: =IF(Table1[[#This Row],[New LTD]]<=7,"Yes","No") -> Yes | J286: =IF(V286>20%,"Yes","No") -> No | K286: Europe | L286: Germany | M286: Munich | N286: Small Business | O286: Online | P286: M. Rossi | Q286: Accessories | R286: ACC-2761 | S286: 910.63 | T286: 1269.4 | U286: =ABS(T286) -> 1269.4 | V286: 0.068 | W286: 9 | X286: =U286*W286*(1-V286) -> 10647.727 | Y286: =S286*W286 -> 8195.67 | Z286: =X286-Y286 -> 2452.0572 | AA286: =IF(X286=0, 0, Z286/ X286) -> 0.23028926 | AB286: =_xlfn.CONCAT(MONTH(B286),"-",YEAR(B286)) -> 3-2024 | AC286: ="Q"&ROUNDUP(MONTH(B286)/3,0)&"-"&YEAR(B286) -> Q1-2024 | AD286: =_xlfn.CONCAT(K286," →",L286," →",M286) -> Europe →Germany →Munich | AE286: =IF(T286<=LowerCutOff,"Low", IF(T286<=HigherCutOff,"Medium","High")) -> Medium | AF286: =TEXT(Table1[[#This Row],[OrderDate]],"MMM") -> Mar | AG286: =TEXT(Table1[[#This Row],[OrderDate]],"YYYY") -> 2024 | AI286: =IF(Table1[[#This Row],[RequiredDate]]<Table1[[#This Row],[OrderDate]], Table1[[#This Row],[OrderDate]]+7, Table1[[#This Row],[RequiredDate]]) -> 45372 | AJ286: =IF(Dashboard!$D$3>'Staging Data'!V286,'Staging Data'!V286,Dashboard!D$3) -> 0.068 | AK286: =(100%+Dashboard!$D$4)*'Staging Data'!S286 -> 956.1615 | AL286: =(100%+Dashboard!$D$5)*'Staging Data'!W286 -> 10.35
A287: ORD-2024-446030 | B287: 45374 | C287: 45377 | D287: =IF(Table1[[#This Row],[RequiredDate]]<Table1[[#This Row],[OrderDate]],Table1[[#This Row],[RequiredDate]],Table1[[#This Row],[OrderDate]]) -> 45374 | E287: =IF(Table1[[#This Row],[RequiredDate]]>Table1[[#This Row],[OrderDate]],Table1[[#This Row],[RequiredDate]],Table1[[#This Row],[OrderDate]]) -> 45377 | F287: =Table1[[#This Row],[New RD]]-Table1[[#This Row],[new od]] -> 3 | G287: =IF(Table1[[#This Row],[RequiredDate]]<Table1[[#This Row],[OrderDate]], Table1[[#This Row],[OrderDate]]+7, Table1[[#This Row],[RequiredDate]]) -> 45377 | H287: =G287-B287 -> 3 | I287: =IF(Table1[[#This Row],[New LTD]]<=7,"Yes","No") -> Yes | J287: =IF(V287>20%,"Yes","No") -> No | K287: Asia | L287: India | M287: Bengaluru | N287: Education | O287: Direct | P287: G. Dubois | Q287: Phones | R287: PHN-4346 | S287: 382.21 | T287: 571.89 | U287: =ABS(T287) -> 571.89 | V287: 0.148 | W287: 26 | X287: =U287*W287*(1-V287) -> 12668.507 | Y287: =S287*W287 -> 9937.46 | Z287: =X287-Y287 -> 2731.0473 | AA287: =IF(X287=0, 0, Z287/ X287) -> 0.21557767 | AB287: =_xlfn.CONCAT(MONTH(B287),"-",YEAR(B287)) -> 3-2024 | AC287: ="Q"&ROUNDUP(MONTH(B287)/3,0)&"-"&YEAR(B287) -> Q1-2024 | AD287: =_xlfn.CONCAT(K287," →",L287," →",M287) -> Asia →India →Bengaluru | AE287: =IF(T287<=LowerCutOff,"Low", IF(T287<=HigherCutOff,"Medium","High")) -> Low | AF287: =TEXT(Table1[[#This Row],[OrderDate]],"MMM") -> Mar | AG287: =TEXT(Table1[[#This Row],[OrderDate]],"YYYY") -> 2024 | AI287: =IF(Table1[[#This Row],[RequiredDate]]<Table1[[#This Row],[OrderDate]], Table1[[#This Row],[OrderDate]]+7, Table1[[#This Row],[RequiredDate]]) -> 45377 | AJ287: =IF(Dashboard!$D$3>'Staging Data'!V287,'Staging Data'!V287,Dashboard!D$3) -> 0.148 | AK287: =(100%+Dashboard!$D$4)*'Staging Data'!S287 -> 401.3205 | AL287: =(100%+Dashboard!$D$5)*'Staging Data'!W287 -> 29.9
A288: ORD-2024-207096 | B288: 45377 | C288: 45387 | D288: =IF(Table1[[#This Row],[RequiredDate]]<Table1[[#This Row],[OrderDate]],Table1[[#This Row],[RequiredDate]],Table1[[#This Row],[OrderDate]]) -> 45377 | E288: =IF(Table1[[#This Row],[RequiredDate]]>Table1[[#This Row],[OrderDate]],Table1[[#This Row],[RequiredDate]],Table1[[#This Row],[OrderDate]]) -> 45387 | F288: =Table1[[#This Row],[New RD]]-Table1[[#This Row],[new od]] -> 10 | G288: =IF(Table1[[#This Row],[RequiredDate]]<Table1[[#This Row],[OrderDate]], Table1[[#This Row],[OrderDate]]+7, Table1[[#This Row],[RequiredDate]]) -> 45387 | H288: =G288-B288 -> 10 | I288: =IF(Table1[[#This Row],[New LTD]]<=7,"Yes","No") -> No | J288: =IF(V288>20%,"Yes","No") -> No | K288: Americas | L288: USA | M288: Austin | N288: Consumer | O288: Direct | P288: J. Njeri | Q288: Monitors | R288: MON-5444 | S288: 5.66 | T288: 4.22 | U288: =ABS(T288) -> 4.22 | V288: 0.119 | W288: 18 | X288: =U288*W288*(1-V288) -> 66.92076 | Y288: =S288*W288 -> 101.88 | Z288: =X288-Y288 -> -34.95924 | AA288: =IF(X288=0, 0, Z288/ X288) -> -0.52239753 | AB288: =_xlfn.CONCAT(MONTH(B288),"-",YEAR(B288)) -> 3-2024 | AC288: ="Q"&ROUNDUP(MONTH(B288)/3,0)&"-"&YEAR(B288) -> Q1-2024 | AD288: =_xlfn.CONCAT(K288," →",L288," →",M288) -> Americas →USA →Austin | AE288: =IF(T288<=LowerCutOff,"Low", IF(T288<=HigherCutOff,"Medium","High")) -> Low | AF288: =TEXT(Table1[[#This Row],[OrderDate]],"MMM") -> Mar | AG288: =TEXT(Table1[[#This Row],[OrderDate]],"YYYY") -> 2024 | AI288: =IF(Table1[[#This Row],[RequiredDate]]<Table1[[#This Row],[OrderDate]], Table1[[#This Row],[OrderDate]]+7, Table1[[#This Row],[RequiredDate]]) -> 45387 | AJ288: =IF(Dashboard!$D$3>'Staging Data'!V288,'Staging Data'!V288,Dashboard!D$3) -> 0.119 | AK288: =(100%+Dashboard!$D$4)*'Staging Data'!S288 -> 5.943 | AL288: =(100%+Dashboard!$D$5)*'Staging Data'!W288 -> 20.7
A289: ORD-2024-948800 | B289: 45378 | C289: 45393 | D289: =IF(Table1[[#This Row],[RequiredDate]]<Table1[[#This Row],[OrderDate]],Table1[[#This Row],[RequiredDate]],Table1[[#This Row],[OrderDate]]) -> 45378 | E289: =IF(Table1[[#This Row],[RequiredDate]]>Table1[[#This Row],[OrderDate]],Table1[[#This Row],[RequiredDate]],Table1[[#This Row],[OrderDate]]) -> 45393 | F289: =Table1[[#This Row],[New RD]]-Table1[[#This Row],[new od]] -> 15 | G289: =IF(Table1[[#This Row],[RequiredDate]]<Table1[[#This Row],[OrderDate]], Table1[[#This Row],[OrderDate]]+7, Table1[[#This Row],[RequiredDate]]) -> 45393 | H289: =G289-B289 -> 15 | I289: =IF(Table1[[#This Row],[New LTD]]<=7,"Yes","No") -> No | J289: =IF(V289>20%,"Yes","No") -> No | K289: Americas | L289: USA | M289: San Francisco | N289: Small Business | O289: Direct | P289: O. Wang | Q289: Networking | R289: NET-5523 | S289: 1338.35 | T289: 2247.14 | U289: =ABS(T289) -> 2247.14 | V289: 0.115 | W289: 40 | X289: =U289*W289*(1-V289) -> 79548.756 | Y289: =S289*W289 -> 53534 | Z289: =X289-Y289 -> 26014.756 | AA289: =IF(X289=0, 0, Z289/ X289) -> 0.32702907 | AB289: =_xlfn.CONCAT(MONTH(B289),"-",YEAR(B289)) -> 3-2024 | AC289: ="Q"&ROUNDUP(MONTH(B289)/3,0)&"-"&YEAR(B289) -> Q1-2024 | AD289: =_xlfn.CONCAT(K289," →",L289," →",M289) -> Americas →USA →San Francisco | AE289: =IF(T289<=LowerCutOff,"Low", IF(T289<=HigherCutOff,"Medium","High")) -> High | AF289: =TEXT(Table1[[#This Row],[OrderDate]],"MMM") -> Mar | AG289: =TEXT(Table1[[#This Row],[OrderDate]],"YYYY") -> 2024 | AI289: =IF(Table1[[#This Row],[RequiredDate]]<Table1[[#This Row],[OrderDate]], Table1[[#This Row],[OrderDate]]+7, Table1[[#This Row],[RequiredDate]]) -> 45393 | AJ289: =IF(Dashboard!$D$3>'Staging Data'!V289,'Staging Data'!V289,Dashboard!D$3) -> 0.115 | AK289: =(100%+Dashboard!$D$4)*'Staging Data'!S289 -> 1405.2675 | AL289: =(100%+Dashboard!$D$5)*'Staging Data'!W289 -> 46
A290: ORD-2024-897622 | B290: 45381 | C290: 45406 | D290: =IF(Table1[[#This Row],[RequiredDate]]<Table1[[#This Row],[OrderDate]],Table1[[#This Row],[RequiredDate]],Table1[[#This Row],[OrderDate]]) -> 45381 | E290: =IF(Table1[[#This Row],[RequiredDate]]>Table1[[#This Row],[OrderDate]],Table1[[#This Row],[RequiredDate]],Table1[[#This Row],[OrderDate]]) -> 45406 | F290: =Table1[[#This Row],[New RD]]-Table1[[#This Row],[new od]] -> 25 | G290: =IF(Table1[[#This Row],[RequiredDate]]<Table1[[#This Row],[OrderDate]], Table1[[#This Row],[OrderDate]]+7, Table1[[#This Row],[RequiredDate]]) -> 45406 | H290: =G290-B290 -> 25 | I290: =IF(Table1[[#This Row],[New LTD]]<=7,"Yes","No") -> No | J290: =IF(V290>20%,"Yes","No") -> No | K290: Americas | L290: USA | M290: Austin | N290: Non-Profit | O290: Online | P290: G. Dubois | Q290: Laptops | R290: LAP-2846 | S290: 160.82 | T290: 258.52 | U290: =ABS(T290) -> 258.52 | V290: 0.13 | W290: 17 | X290: =U290*W290*(1-V290) -> 3823.5108 | Y290: =S290*W290 -> 2733.94 | Z290: =X290-Y290 -> 1089.5708 | AA290: =IF(X290=0, 0, Z290/ X290) -> 0.28496606 | AB290: =_xlfn.CONCAT(MONTH(B290),"-",YEAR(B290)) -> 3-2024 | AC290: ="Q"&ROUNDUP(MONTH(B290)/3,0)&"-"&YEAR(B290) -> Q1-2024 | AD290: =_xlfn.CONCAT(K290," →",L290," →",M290) -> Americas →USA →Austin | AE290: =IF(T290<=LowerCutOff,"Low", IF(T290<=HigherCutOff,"Medium","High")) -> Low | AF290: =TEXT(Table1[[#This Row],[OrderDate]],"MMM") -> Mar | AG290: =TEXT(Table1[[#This Row],[OrderDate]],"YYYY") -> 2024 | AI290: =IF(Table1[[#This Row],[RequiredDate]]<Table1[[#This Row],[OrderDate]], Table1[[#This Row],[OrderDate]]+7, Table1[[#This Row],[RequiredDate]]) -> 45406 | AJ290: =IF(Dashboard!$D$3>'Staging Data'!V290,'Staging Data'!V290,Dashboard!D$3) -> 0.13 | AK290: =(100%+Dashboard!$D$4)*'Staging Data'!S290 -> 168.861 | AL290: =(100%+Dashboard!$D$5)*'Staging Data'!W290 -> 19.55
A291: ORD-2024-745822 | B291: 45382 | C291: 45399 | D291: =IF(Table1[[#This Row],[RequiredDate]]<Table1[[#This Row],[OrderDate]],Table1[[#This Row],[RequiredDate]],Table1[[#This Row],[OrderDate]]) -> 45382 | E291: =IF(Table1[[#This Row],[RequiredDate]]>Table1[[#This Row],[OrderDate]],Table1[[#This Row],[RequiredDate]],Table1[[#This Row],[OrderDate]]) -> 45399 | F291: =Table1[[#This Row],[New RD]]-Table1[[#This Row],[new od]] -> 17 | G291: =IF(Table1[[#This Row],[RequiredDate]]<Table1[[#This Row],[OrderDate]], Table1[[#This Row],[OrderDate]]+7, Table1[[#This Row],[RequiredDate]]) -> 45399 | H291: =G291-B291 -> 17 | I291: =IF(Table1[[#This Row],[New LTD]]<=7,"Yes","No") -> No | J291: =IF(V291>20%,"Yes","No") -> No | K291: Europe | L291: Germany | M291: Frankfurt | N291: Education | O291: Direct | P291: H. Kim | Q291: Monitors | R291: MON-8651 | S291: 1025.51 | T291: 1436.54 | U291: =ABS(T291) -> 1436.54 | V291: 0.139 | W291: 28 | X291: =U291*W291*(1-V291) -> 34632.106 | Y291: =S291*W291 -> 28714.28 | Z291: =X291-Y291 -> 5917.8263 | AA291: =IF(X291=0, 0, Z291/ X291) -> 0.17087688 | AB291: =_xlfn.CONCAT(MONTH(B291),"-",YEAR(B291)) -> 3-2024 | AC291: ="Q"&ROUNDUP(MONTH(B291)/3,0)&"-"&YEAR(B291) -> Q1-2024 | AD291: =_xlfn.CONCAT(K291," →",L291," →",M291) -> Europe →Germany →Frankfurt | AE291: =IF(T291<=LowerCutOff,"Low", IF(T291<=HigherCutOff,"Medium","High")) -> Medium | AF291: =TEXT(Table1[[#This Row],[OrderDate]],"MMM") -> Mar | AG291: =TEXT(Table1[[#This Row],[OrderDate]],"YYYY") -> 2024 | AI291: =IF(Table1[[#This Row],[RequiredDate]]<Table1[[#This Row],[OrderDate]], Table1[[#This Row],[OrderDate]]+7, Table1[[#This Row],[RequiredDate]]) -> 45399 | AJ291: =IF(Dashboard!$D$3>'Staging Data'!V291,'Staging Data'!V291,Dashboard!D$3) -> 0.139 | AK291: =(100%+Dashboard!$D$4)*'Staging Data'!S291 -> 1076.7855 | AL291: =(100%+Dashboard!$D$5)*'Staging Data'!W291 -> 32.2
A292: ORD-2024-219735 | B292: 45385 | C292: 45389 | D292: =IF(Table1[[#This Row],[RequiredDate]]<Table1[[#This Row],[OrderDate]],Table1[[#This Row],[RequiredDate]],Table1[[#This Row],[OrderDate]]) -> 45385 | E292: =IF(Table1[[#This Row],[RequiredDate]]>Table1[[#This Row],[OrderDate]],Table1[[#This Row],[RequiredDate]],Table1[[#This Row],[OrderDate]]) -> 45389 | F292: =Table1[[#This Row],[New RD]]-Table1[[#This Row],[new od]] -> 4 | G292: =IF(Table1[[#This Row],[RequiredDate]]<Table1[[#This Row],[OrderDate]], Table1[[#This Row],[OrderDate]]+7, Table1[[#This Row],[RequiredDate]]) -> 45389 | H292: =G292-B292 -> 4 | I292: =IF(Table1[[#This Row],[New LTD]]<=7,"Yes","No") -> Yes | J292: =IF(V292>20%,"Yes","No") -> No | K292: Americas | L292: Brazil | M292: Brasília | N292: Non-Profit | O292: Direct | P292: N. Brown | Q292: Phones | R292: PHN-5445 | S292: 1023.27 | T292: 1343.64 | U292: =ABS(T292) -> 1343.64 | V292: 0.133 | W292: 7 | X292: =U292*W292*(1-V292) -> 8154.5512 | Y292: =S292*W292 -> 7162.89 | Z292: =X292-Y292 -> 991.66116 | AA292: =IF(X292=0, 0, Z292/ X292) -> 0.12160831 | AB292: =_xlfn.CONCAT(MONTH(B292),"-",YEAR(B292)) -> 4-2024 | AC292: ="Q"&ROUNDUP(MONTH(B292)/3,0)&"-"&YEAR(B292) -> Q2-2024 | AD292: =_xlfn.CONCAT(K292," →",L292," →",M292) -> Americas →Brazil →Brasília | AE292: =IF(T292<=LowerCutOff,"Low", IF(T292<=HigherCutOff,"Medium","High")) -> Medium | AF292: =TEXT(Table1[[#This Row],[OrderDate]],"MMM") -> Apr | AG292: =TEXT(Table1[[#This Row],[OrderDate]],"YYYY") -> 2024 | AI292: =IF(Table1[[#This Row],[RequiredDate]]<Table1[[#This Row],[OrderDate]], Table1[[#This Row],[OrderDate]]+7, Table1[[#This Row],[RequiredDate]]) -> 45389 | AJ292: =IF(Dashboard!$D$3>'Staging Data'!V292,'Staging Data'!V292,Dashboard!D$3) -> 0.133 | AK292: =(100%+Dashboard!$D$4)*'Staging Data'!S292 -> 1074.4335 | AL292: =(100%+Dashboard!$D$5)*'Staging Data'!W292 -> 8.05
A293: ORD-2024-510591 | B293: 45385 | C293: 45403 | D293: =IF(Table1[[#This Row],[RequiredDate]]<Table1[[#This Row],[OrderDate]],Table1[[#This Row],[RequiredDate]],Table1[[#This Row],[OrderDate]]) -> 45385 | E293: =IF(Table1[[#This Row],[RequiredDate]]>Table1[[#This Row],[OrderDate]],Table1[[#This Row],[RequiredDate]],Table1[[#This Row],[OrderDate]]) -> 45403 | F293: =Table1[[#This Row],[New RD]]-Table1[[#This Row],[new od]] -> 18 | G293: =IF(Table1[[#This Row],[RequiredDate]]<Table1[[#This Row],[OrderDate]], Table1[[#This Row],[OrderDate]]+7, Table1[[#This Row],[RequiredDate]]) -> 45403 | H293: =G293-B293 -> 18 | I293: =IF(Table1[[#This Row],[New LTD]]<=7,"Yes","No") -> No | J293: =IF(V293>20%,"Yes","No") -> No | K293: Americas | L293: Brazil | M293: Brasília | N293: Small Business | O293: Distributor | P293: B. Chen | Q293: Networking | R293: NET-3850 | S293: 1176.69 | T293: 2201.54 | U293: =ABS(T293) -> 2201.54 | V293: 0.17 | W293: 27 | X293: =U293*W293*(1-V293) -> 49336.511 | Y293: =S293*W293 -> 31770.63 | Z293: =X293-Y293 -> 17565.881 | AA293: =IF(X293=0, 0, Z293/ X293) -> 0.35604223 | AB293: =_xlfn.CONCAT(MONTH(B293),"-",YEAR(B293)) -> 4-2024 | AC293: ="Q"&ROUNDUP(MONTH(B293)/3,0)&"-"&YEAR(B293) -> Q2-2024 | AD293: =_xlfn.CONCAT(K293," →",L293," →",M293) -> Americas →Brazil →Brasília | AE293: =IF(T293<=LowerCutOff,"Low", IF(T293<=HigherCutOff,"Medium","High")) -> High | AF293: =TEXT(Table1[[#This Row],[OrderDate]],"MMM") -> Apr | AG293: =TEXT(Table1[[#This Row],[OrderDate]],"YYYY") -> 2024 | AI293: =IF(Table1[[#This Row],[RequiredDate]]<Table1[[#This Row],[OrderDate]], Table1[[#This Row],[OrderDate]]+7, Table1[[#This Row],[RequiredDate]]) -> 45403 | AJ293: =IF(Dashboard!$D$3>'Staging Data'!V293,'Staging Data'!V293,Dashboard!D$3) -> 0.17 | AK293: =(100%+Dashboard!$D$4)*'Staging Data'!S293 -> 1235.5245 | AL293: =(100%+Dashboard!$D$5)*'Staging Data'!W293 -> 31.05
